<mujoco model="e1">
    <compiler angle="radian" meshdir="meshes/" />
    <size njmax="500" nconmax="100" />
    <asset>
        <mesh name="pelvis" file="pelvis_Link.STL" />
        <mesh name="torso_link" file="torso_link.STL" />
        <mesh name="leg_l1_link" file="leg_l1_link.STL" />
        <mesh name="leg_l2_link_144" file="leg_l2_link_144.STL" />
        <mesh name="leg_l3_link_144" file="leg_l3_link_144.STL" />
        <mesh name="leg_l4_link" file="leg_l4_link.STL" />
        <mesh name="leg_l5_link" file="leg_l5_link.STL" />
        <mesh name="leg_l6_link" file="leg_l6_link.STL" />
        <mesh name="leg_r1_link" file="leg_r1_link.STL" />
        <mesh name="leg_r2_link_144" file="leg_r2_link_144.STL" />
        <mesh name="leg_r3_link_144" file="leg_r3_link_144.STL" />
        <mesh name="leg_r4_link" file="leg_r4_link.STL" />
        <mesh name="leg_r5_link" file="leg_r5_link.STL" />
        <mesh name="leg_r6_link" file="leg_r6_link.STL" />
        <mesh name="arm_l1_link" file="arm_l1_link.STL" />
        <mesh name="arm_l2_link" file="arm_l2_link.STL" />
        <mesh name="arm_r3_link" file="arm_r3_link.STL" />
        <mesh name="arm_l4_link" file="arm_l4_link.STL" />
        <mesh name="arm_r1_link" file="arm_r1_link.STL" />
        <mesh name="arm_r2_link" file="arm_r2_link.STL" />
        <mesh name="arm_r4_link" file="arm_r4_link.STL" />
    </asset>
    <worldbody>
        <body name="pelvis_link" pos="0 0 0.76">
            <inertial pos="0.00049408 0.000243546 0.0350138" quat="0.99995 -0.00871458 -0.00482254 0.000136248" mass="5.38002" diaginertia="0.0242082 0.0220955 0.0146869" />
            <joint name="floating_base_joint" type="free" />
            <geom type="mesh" contype="0" conaffinity="0" group="1" rgba="0.64706 0.61961 0.58824 1" mesh="pelvis" />
            <geom type="mesh" rgba="0.64706 0.61961 0.58824 1" mesh="pelvis" />
            <geom size="0.0075 0.0075 0.002" type="box" contype="0" conaffinity="0" group="1" />
                
            <body name="leg_l1_link" pos="0 0.1413 0">
                <inertial pos="0.000198 -0.007668 -0.027055" quat="0.803911 0.594673 0.00416077 0.00860883" mass="1.7066" diaginertia="0.00326347 0.00244049 0.00185104" />
                <joint name="leg_l1_joint" pos="0 0 0" axis="0 1 0" limited="true" range="-2.53 2.53" />
                <geom type="mesh" contype="0" conaffinity="0" group="1" rgba="0.64706 0.61961 0.58824 1" mesh="leg_l1_link" />
                <geom type="mesh" rgba="0.64706 0.61961 0.58824 1" mesh="leg_l1_link" />
                <body name="leg_l2_link" pos="0 0 -0.0285">
                    <inertial pos="0.000169 1.1e-05 -0.097717" quat="0.705185 0.0810174 0.0812018 0.699684" mass="2.05855" diaginertia="0.00452202 0.00414549 0.00344249" />
                    <joint name="leg_l2_joint" pos="0 0 0" axis="1 0 0" limited="true" range="-0.611 3.23" />
                    <geom type="mesh" contype="0" conaffinity="0" group="1" rgba="0.64706 0.61961 0.58824 1" mesh="leg_l2_link_144" />
                    <geom type="mesh" rgba="0.64706 0.61961 0.58824 1" mesh="leg_l2_link_144" />
                    <body name="leg_l3_link" pos="0 0 -0.1418">
                        <inertial pos="-0.001884 0.000196 -0.102645" quat="0.697437 0.0385379 0.0379285 0.714603" mass="2.34422" diaginertia="0.00903058 0.00804782 0.0032976" />
                        <joint name="leg_l3_joint" pos="0 0 0" axis="0 0 1" limited="true" range="-1.05 1.05" />
                        <geom type="mesh" contype="0" conaffinity="0" group="1" rgba="0.64706 0.61961 0.58824 1" mesh="leg_l3_link_144" />
                        <geom type="mesh" rgba="0.64706 0.61961 0.58824 1" mesh="leg_l3_link_144" />
                        <body name="leg_l4_link" pos="-0.008 0 -0.1357">
                            <inertial pos="-0.002981 0.002004 -0.175957" quat="0.741023 -0.00212634 0.0129814 0.671351" mass="2.68581" diaginertia="0.0219449 0.0212371 0.00289196" />
                            <joint name="leg_l4_joint" pos="0 0 0" axis="0 1 0" limited="true" range="-0.349 2.355" />
                            <geom type="mesh" contype="0" conaffinity="0" group="1" rgba="0.64706 0.61961 0.58824 1" mesh="leg_l4_link" />
                            <geom type="mesh" rgba="0.64706 0.61961 0.58824 1" mesh="leg_l4_link" />
                            <body name="leg_l5_link" pos="0 0 -0.35">
                                <inertial pos="0 0 0" quat="0 0.707107 0 0.707107" mass="0.088534" diaginertia="3.1681e-05 3.1274e-05 3.0975e-05" />
                                <joint name="leg_l5_joint" pos="0 0 0" axis="0 1 0" limited="true" range="-0.785 1.05" />
                                <geom type="mesh" contype="0" conaffinity="0" group="1" rgba="0.64706 0.61961 0.58824 1" mesh="leg_l5_link" />
                                <body name="leg_l6_link" pos="0 0 0">
                                    <inertial pos="-0.000705 1.4e-05 -0.028746" mass="0.611" diaginertia="0.01 0.01 0.01" />
                                    <joint name="leg_l6_joint" pos="0 0 0" axis="1 0 0" limited="true" range="-0.26 0.26" />
                                    <geom type="mesh" contype="0" conaffinity="0" group="1" rgba="0.64706 0.61961 0.58824 1" mesh="leg_l6_link" />
                                    <geom size="0.11 0.03 0.005" pos="0.01 0 -0.05" type="box" rgba="0.64706 0.61961 0.58824 1" />
                                </body>
                            </body>
                        </body>
                    </body>
                </body>
            </body>
            <body name="leg_r1_link" pos="0 -0.1413 0">
                <inertial pos="0.000198 0.007673 -0.027057" quat="0.593758 0.804592 -0.00829045 -0.00394138" mass="1.7066" diaginertia="0.00326343 0.00244613 0.00184643" />
                <joint name="leg_r1_joint" pos="0 0 0" axis="0 1 0" limited="true" range="-2.53 2.53" />
                <geom type="mesh" contype="0" conaffinity="0" group="1" rgba="0.64706 0.61961 0.58824 1" mesh="leg_r1_link" />
                <geom type="mesh" rgba="0.64706 0.61961 0.58824 1" mesh="leg_r1_link" />
                <body name="leg_r2_link" pos="0 0 -0.0285">
                    <inertial pos="0.000169 -1.1e-05 -0.097718" quat="0.702427 0.0812195 0.0812195 0.702427" mass="2.05855" diaginertia="0.004521 0.00414456 0.00344244" />
                    <joint name="leg_r2_joint" pos="0 0 0" axis="1 0 0" limited="true" range="-3.23 0.611" />
                    <geom type="mesh" contype="0" conaffinity="0" group="1" rgba="0.64706 0.61961 0.58824 1" mesh="leg_r2_link_144" />
                    <geom type="mesh" rgba="0.64706 0.61961 0.58824 1" mesh="leg_r2_link_144" />
                    <body name="leg_r3_link" pos="0 0 -0.1418">
                        <inertial pos="-0.001885 -0.000196 -0.102649" quat="0.714631 0.0376084 0.0382139 0.697444" mass="2.34422" diaginertia="0.00903058 0.00804891 0.00329651" />
                        <joint name="leg_r3_joint" pos="0 0 0" axis="0 0 1" limited="true" range="-1.05 1.05" />
                        <geom type="mesh" contype="0" conaffinity="0" group="1" rgba="0.64706 0.61961 0.58824 1" mesh="leg_r3_link_144" />
                        <geom type="mesh" rgba="0.64706 0.61961 0.58824 1" mesh="leg_r3_link_144" />
                        <body name="leg_r4_link" pos="-0.008 0 -0.1357">
                            <inertial pos="-0.002918 -0.001931 -0.17596" quat="0.67014 0.0136932 -0.00270144 0.742104" mass="2.6855" diaginertia="0.0219489 0.0212368 0.0028933" />
                            <joint name="leg_r4_joint" pos="0 0 0" axis="0 1 0" limited="true" range="-0.349 2.355" />
                            <geom type="mesh" contype="0" conaffinity="0" group="1" rgba="0.64706 0.61961 0.58824 1" mesh="leg_r4_link" />
                            <geom type="mesh" rgba="0.64706 0.61961 0.58824 1" mesh="leg_r4_link" />
                            <body name="leg_r5_link" pos="0 0 -0.35">
                                <inertial pos="0 0 0" quat="0.5 0.5 0.5 0.5" mass="0.088534" diaginertia="3.1274e-05 3.1274e-05 3.0975e-05" />
                                <joint name="leg_r5_joint" pos="0 0 0" axis="0 1 0" limited="true" range="-0.785 1.05" />
                                <geom type="mesh" contype="0" conaffinity="0" group="1" rgba="0.64706 0.61961 0.58824 1" mesh="leg_r5_link" />
                                <body name="leg_r6_link" pos="0 0 0">
                                    <inertial pos="-0.000705 1.4e-05 -0.028746" mass="0.611" diaginertia="0.01 0.01 0.01" />
                                    <joint name="leg_r6_joint" pos="0 0 0" axis="1 0 0" limited="true" range="-0.26 0.26" />
                                    <geom type="mesh" contype="0" conaffinity="0" group="1" rgba="0.64706 0.61961 0.58824 1" mesh="leg_r6_link" />
                                    <geom size="0.11 0.03 0.005" pos="0.01 0 -0.05" type="box" rgba="0.64706 0.61961 0.58824 1" />
                                </body>
                            </body>
                        </body>
                    </body>
                </body>
            </body>

            <body name="torso_link" pos="0 0 0.1343">
                <inertial pos="0.000495 3.1e-05 0.141036" quat="0.999987 0.00307359 -0.00388752 -0.000863408" mass="11.6367" diaginertia="0.258894 0.185102 0.126145" />
                <joint name="waist_joint" pos="0 0 0" axis="0 0 1" limited="true" range="-1.57 1.57" />
                    <geom type="mesh" contype="0" conaffinity="0" group="1" rgba="0.7 0.7 0.7 1" mesh="torso_link" />
                    <geom type="mesh" rgba="0.7 0.7 0.7 1" mesh="torso_link" />
                    <body name="arm_l1_link" pos="0 0.24499 0.242">
                        <inertial pos="-0.002019 -0.003955 0.000337" quat="0.703626 0.70939 0.036453 0.0186506" mass="0.707077" diaginertia="0.000720767 0.00051688 0.000450353" />
                        <joint name="arm_l1_joint" pos="0 0 0" axis="0 1 0" limited="true" range="-1.57 1.57" />
                        <geom type="mesh" contype="0" conaffinity="0" group="1" rgba="0.64706 0.61961 0.58824 1" mesh="arm_l1_link" />
                        <geom type="mesh" rgba="0.64706 0.61961 0.58824 1" mesh="arm_l1_link" />
                        <body name="arm_l2_link" pos="0 0 0">
                            <inertial pos="0.00112 0.000212 -0.080154" quat="0.70026 0.0665473 0.0594184 0.708291" mass="0.384698" diaginertia="0.000483022 0.000453948 0.00026503" />
                            <joint name="arm_l2_joint" pos="0 0 0" axis="1 0 0" limited="true" range="-1.57 1.57" />
                            <geom type="mesh" contype="0" conaffinity="0" group="1" rgba="0.64706 0.61961 0.58824 1" mesh="arm_l2_link" />
                            <geom type="mesh" rgba="0.64706 0.61961 0.58824 1" mesh="arm_l2_link" />
                            <body name="arm_l3_link" pos="0 0 -0.1247">
                                <inertial pos="0.000158 0.000723 0.030197" quat="0.702372 0.00361834 -0.00523981 0.711782" mass="0.518309" diaginertia="0.00171824 0.00164599 0.000282768" />
                                <joint name="arm_l3_joint" pos="0 0 0" axis="0 0 1" limited="true" range="-1.57 1.57" />
                                <geom type="mesh" contype="0" conaffinity="0" group="1" rgba="0.64706 0.61961 0.58824 1" mesh="arm_r3_link" />
                                <geom type="mesh" rgba="0.64706 0.61961 0.58824 1" mesh="arm_r3_link" />
                                <body name="arm_l4_link" pos="0 -0.0013 -0.1386" quat="0.707388 0 -0.706825 0">
                                    <inertial pos="-7.87149e-05 0.00176053 -0.124343" quat="0.999936 -0.0112838 -0.00052883 -0.00100654" mass="0.249613" diaginertia="0.00216344 0.00214044 0.000107995" />
                                    <joint name="arm_l4_joint" pos="0 0 0" axis="0 1 0" limited="true" range="-1.57 1.57" />
                                    <geom type="mesh" contype="0" conaffinity="0" group="1" rgba="0.64706 0.61961 0.58824 1" mesh="arm_l4_link" />
                                    <geom type="mesh" rgba="0.64706 0.61961 0.58824 1" mesh="arm_l4_link" />
                                    <geom size="0.03 0.03 0.03" pos="0 0 -0.28" type="box" contype="0" conaffinity="0" group="1" />
                                    <geom size="0.03 0.03 0.03" pos="0 0 -0.28" type="box" />
                                </body>
                            </body>
                        </body>
                    </body>
                
                    <body name="arm_r1_link" pos="0 -0.24499 0.242">
                        <inertial pos="-0.00201 0.004013 0.000523" quat="0.710233 0.702957 -0.0205319 -0.0316167" mass="0.707077" diaginertia="0.000815526 0.000614962 0.000543513" />
                        <joint name="arm_r1_joint" pos="0 0 0" axis="0 1 0" limited="true" range="-1.57 1.57" />
                        <geom type="mesh" contype="0" conaffinity="0" group="1" rgba="0.64706 0.61961 0.58824 1" mesh="arm_r1_link" />
                        <geom type="mesh" rgba="0.64706 0.61961 0.58824 1" mesh="arm_r1_link" />
                        <body name="arm_r2_link" pos="0 0 0">
                            <inertial pos="0.000914 -9.9e-05 -0.080154" quat="0.694752 0.0661645 0.068214 0.712944" mass="0.384698" diaginertia="0.000484026 0.00045272 0.000264253" />
                            <joint name="arm_r2_joint" pos="0 0 0" axis="1 0 0" limited="true" range="-1.57 1.57" />
                            <geom type="mesh" contype="0" conaffinity="0" group="1" rgba="0.64706 0.61961 0.58824 1" mesh="arm_r2_link" />
                            <geom type="mesh" rgba="0.64706 0.61961 0.58824 1" mesh="arm_r2_link" />
                            <body name="arm_r3_link" pos="0 0 -0.1247">
                                <inertial pos="0.000169 -0.000768 0.030193" quat="0.711822 -0.00449585 0.00288481 0.70234" mass="0.518309" diaginertia="0.00171817 0.00164599 0.000282837" />
                                <joint name="arm_r3_joint" pos="0 0 0" axis="0 0 1" limited="true" range="-1.57 1.57" />
                                <geom type="mesh" contype="0" conaffinity="0" group="1" rgba="0.64706 0.61961 0.58824 1" mesh="arm_r3_link" />
                                <geom type="mesh" rgba="0.64706 0.61961 0.58824 1" mesh="arm_r3_link" />
                                <body name="arm_r4_link" pos="0 0.0013 -0.1386" quat="0.707388 0 -0.706825 0">
                                    <inertial pos="-7.87149e-05 -0.00176053 -0.124343" quat="0.999936 0.0112838 -0.00052883 0.00100654" mass="0.249613" diaginertia="0.00216344 0.00214044 0.000107995" />
                                    <joint name="arm_r4_joint" pos="0 0 0" axis="0 1 0" limited="true" range="-1.57 1.57" />
                                    <geom type="mesh" contype="0" conaffinity="0" group="1" rgba="0.64706 0.61961 0.58824 1" mesh="arm_r4_link" />
                                    <geom type="mesh" rgba="0.64706 0.61961 0.58824 1" mesh="arm_r4_link" />
                                    <geom size="0.03 0.03 0.03" pos="0 0 -0.28" type="box" contype="0" conaffinity="0" group="1" />
                                    <geom size="0.03 0.03 0.03" pos="0 0 -0.28" type="box" />
                                </body>
                            </body>
                        </body>
                    </body>
            </body>

        </body>
    </worldbody>
    <actuator>
    <motor name="leg_l1_joint" joint="leg_l1_joint"/>
    <motor name="leg_l2_joint" joint="leg_l2_joint"/>
    <motor name="leg_l3_joint" joint="leg_l3_joint"/>
    <motor name="leg_l4_joint" joint="leg_l4_joint"/>
    <motor name="leg_l5_joint" joint="leg_l5_joint"/>
    <motor name="leg_l6_joint" joint="leg_l6_joint"/>
    <motor name="leg_r1_joint" joint="leg_r1_joint"/>
    <motor name="leg_r2_joint" joint="leg_r2_joint"/>
    <motor name="leg_r3_joint" joint="leg_r3_joint"/>
    <motor name="leg_r4_joint" joint="leg_r4_joint"/>
    <motor name="leg_r5_joint" joint="leg_r5_joint"/>
    <motor name="leg_r6_joint" joint="leg_r6_joint"/>
    
    <motor name="waist_joint" joint="waist_joint"/>

    <motor name="arm_l1_joint" joint="arm_l1_joint"/>
    <motor name="arm_l2_joint" joint="arm_l2_joint"/>
    <motor name="arm_l3_joint" joint="arm_l3_joint"/>
    <motor name="arm_l4_joint" joint="arm_l4_joint"/>
    <motor name="arm_r1_joint" joint="arm_r1_joint"/>
    <motor name="arm_r2_joint" joint="arm_r2_joint"/>
    <motor name="arm_r3_joint" joint="arm_r3_joint"/>
    <motor name="arm_r4_joint" joint="arm_r4_joint"/>
    </actuator>
</mujoco>
